<?xml version="1.0" ?>
<!-- =================================================================================== -->
<!-- |    This document was autogenerated by xacro from /home/swimming/gcamp_ros2_ws/src/gcamp_ros2_basic/gcamp_gazebo/urdf/skidbot2.urdf.xacro | -->
<!-- |    EDITING THIS FILE BY HAND IS NOT RECOMMENDED                                 | -->
<!-- =================================================================================== -->
<robot xmlns:xacro="http://www.ros.org/wiki/xacro" name="easyai">
  <xacro:property name="PI" value="3.1415926535"/><!--파이 값-->

  <xacro:property name="BASE_LEN" value="0.5"/><!--이지아이 몸통  길이-->
  <xacro:property name="BASE_WID" value="0.3"/><!--이지아이 몸통 너비-->
  <xacro:property name="BASE_HIG" value="0.15"/> <!--이지아이 몸통 높이-->

  <xacro:property name="WHEEL_LEN_SEP" value="0.3"/><!--바퀴 세로 간격-->
  <xacro:property name="WHEEL_WID_SEP" value="0.25"/><!--바퀴 가로 간격-->
  <!-- <xacro:property name="WHEEL_RAD" value="0.159"/>바퀴 반 지름 수정 전 -->
  <xacro:property name="WHEEL_RAD" value="0.085"/><!--바퀴 반 지름 수정 후 (바퀴 베이스 높이 만큼 바퀴 크기 증가)-->
  <xacro:property name="WHEEL_WID" value="0.02"/><!--바퀴 너비-->
  
  <!-- 바퀴 베이스 tf 복잡하여 사용 안함(주석 처리) -->
  <!-- <xacro:property name="WHEEL_BASE_LEN" value="0.05"/>바퀴 베이스 길이
  <xacro:property name="WHEEL_BASE_WID" value="0.1"/>바퀴 베이스 너비
  <xacro:property name="WHEEL_BASE_HIG" value="0.059"/>바퀴 베이스 높이 -->
  
  <xacro:property name="VMS_LEN" value="0.765"/><!--전광판 길이--> 
  <xacro:property name="VMS_WID" value="0.701"/><!--전광판 너비 --> 
  <xacro:property name="VMS_HIG" value="0.134"/><!--전광판 높이-->
  
  <xacro:property name="VMS_CYLINDER_RAD" value="0.020"/><!--전광판 관절 반지름 --> 
  <xacro:property name="VMS_CYLINDER_WID" value="0.380"/><!--전광판 관절 길이 -->
  
  <xacro:property name="VMS_CYLINDER_X_LEN" value="0.235"/><!--전면으로부터 전광판 X축 관절 간격 -->
  
  <xacro:property name="VMS_CYLINDER_BASE_LEN" value="0.035"/><!--전광판 관절 베이스 길이 -->
  <xacro:property name="VMS_CYLINDER_BASE_WID" value="0.01"/><!--전광판 관절 베이스 두께 -->
  <xacro:property name="VMS_CYLINDER_BASE_HIG" value="0.13"/><!--전광판 관절 베이스 높이 -->
  
 
  <!-- 라이다 베이스 tf 복잡하여 사용 안함(주석 처리) -->
  <!-- <xacro:property name="LIDAR_BASE_LEN" value="0.065"/>  라이다 베이스 길이
  <xacro:property name="LIDAR_BASE_WID" value="0.065"/>  라이다 베이스 너비
  <xacro:property name="LIDAR_BASE_HIG" value="0.035"/>  라이다 베이스 높이 -->
  
  <xacro:property name="LIDAR_RAD" value="0.025"/>  <!-- 라이다 길이 -->
  <xacro:property name="LIDAR_HIG" value="0.04"/>  <!-- 라이다 높이(0.06) + 라이다 베이스 높이(0.035)-->
  <!-- 베이스 높이만큼 라이다 높이 증가 -->

  <xacro:property name="F_LIDAR_SEP_LEN" value="0.072"/>  <!-- 전면 라이다  세로 간격  -->
  <xacro:property name="F_LIDAR_SEP_WID" value="0.072"/>  <!-- 전면 라이다 가로 간격 -->
  
  <xacro:property name="B_LIDAR_SEP_LEN" value="0.072"/>  <!-- 후면 라이다  세로 간격  -->
  <xacro:property name="B_LIDAR_SEP_WID" value="0.070"/>  <!-- 후면 라이다 가로 간격 -->

  <xacro:property name="CAMERA_LEN" value="0.025"/>  <!-- 카메라 길이 -->
  <xacro:property name="CAMERA_WID" value="0.1"/>  <!-- 카메라 너비-->
  <xacro:property name="CAMERA_HIG" value="0.04"/>  <!-- 카메라 높이 -->
  <xacro:property name="CAMERA_X_LEN" value="0.042"/>  <!-- 카메라 X 간격 -->
  <xacro:property name="LEFT_CAMERA_Y_LEN" value="0.06"/>  <!-- 왼쪽 카메라 Y 간격 -->
  
  <xacro:property name="LEFT_CAMERA_X_LEN" value="0.06"/>  <!-- 왼쪽 카메라 X축 간격 -->
  <xacro:property name="LEFT_CAMERA_Y_LEN" value="0.07"/>  <!-- 왼쪽 카메라 Y축 간격 -->
  
  <xacro:property name="BACK_CAMERA_X_LEN" value="0.13"/>  <!-- 뒤쪽 카메라 X축 간격 -->
  
  <xacro:property name="GPS_ANTENNA_RAD" value="0.075"/>  <!-- GPS 안테나 반지름 -->
  <xacro:property name="GPS_ANTENNA_HIG" value="0.04"/>  <!-- GPS 안테나 높이 -->
  
  <xacro:property name="BASE_GPS_ANTENNA_SEP" value="0.15"/>  <!-- 몸통 GPS 안테나 간격  -->
  
  <xacro:property name="IMU_LEN" value="0.035"/>  <!-- IMU 길이 -->
  <xacro:property name="IMU_WID" value="0.035"/>  <!-- IMU 너비 -->
  <xacro:property name="IMU_HIG" value="0.01"/>  <!-- IMU 높이 -->
  <xacro:property name="IMU_X_SEP" value="0.225"/>  <!-- IMU X축 간격 -->
  
  
  <xacro:property name="WHEEL_MASS" value="8.0"/><!--바퀴 무게-->
  <xacro:property name="BASE_LINK_MASS" value="200.0"/><!--이지아이 몸통 무게-->
  <xacro:property name="WHEEL_BASE_MASS" value="4.0"/><!--이지아이 몸통 무게-->
  
  <xacro:property name="VMS_MASS" value="20.0"/> <!--전광팡 무게-->
  <xacro:property name="VMS_CYLINDER_MASS" value="10.0"/> <!--전광팡 관절 무게-->
  <xacro:property name="VMS_CYLINDER_BASE_MASS" value="1.0"/> <!--전광팡 관절 베이스 무게-->
  
  <xacro:property name="CAMERA_MASS" value="2.0"/> <!--카메라 무게-->
  
  <xacro:property name="GPS_ANTENNA_MASS" value="2.0"/> <!--GPS 안테나 무게-->  
  
  <xacro:property name="LIDAR_MASS" value="0.265"/> <!--라이다 무게-->
  <xacro:property name="LIDAR_BASE_MASS" value="0.1"/> <!--라이다 베이스 무게-->
  
  <xacro:property name="IMU_MASS" value="0.05"/> <!--IMU 무게-->

<!--<xacro:property name="BATTERY_TANK_LEN" value="0.673"/> --> <!--배터리 탱크 길이-->
<!--<xacro:property name="BATTERY_TANK_HIG" value="다시 재야 함"/> --><!--배터리 탱크 높이--> 
<!--<xacro:property name="BATTERY_TANK_WID" value="0.300"/>--> <!--배터리 탱크 너비--> 


  <material name="dark">
    <color rgba="0.3 0.3 0.3 1.0"/>
  </material>
  
  <material name="mid_dark">
    <color rgba="0.40 0.40 0.40 1.0"/>
  </material>
  
  <material name="gray">
    <color rgba="0.5 0.5 0.5 1.0"/>
  </material>

  <material name="blue_green">
    <color rgba="0 1.0 1.0 1.0"/>
  </material>
  
  <material name="white">
    <color rgba="1.0 1.0 1.0 1.0"/>
  </material>
  
  
  

  <link name="base_link"/>

  <link name="base_chassis">
    <visual>
      <origin xyz="0 0 0" rpy="0 0 0"/>
      <geometry>
        <box size="${BASE_LEN} ${BASE_WID} ${BASE_HIG}"/>
      </geometry>
      <material name="dark"/>
    </visual>
    
    <collision>
      <origin xyz="0 0 0" rpy="0 0 0"/>
      <geometry>
        <box size="${BASE_LEN} ${BASE_WID} ${BASE_HIG}"/>
      </geometry>
    </collision>
    
    <inertial>
      <mass value="${BASE_LINK_MASS}"/>
      <origin xyz="0 0 0" rpy="0 0 0"/>
      <inertia
        ixx="${BASE_LINK_MASS/12.0 * (BASE_WID*BASE_WID + BASE_HIG*BASE_HIG)}"
        iyy="${BASE_LINK_MASS/12.0 * (BASE_LEN*BASE_LEN + BASE_HIG*BASE_HIG)}"
        izz="${BASE_LINK_MASS/12.0 * (BASE_LEN*BASE_LEN + BASE_WID*BASE_WID)}"
        ixy="0.0" ixz="0.0" iyz="0.0"/>
    </inertial>
  </link>



  <link name="imu">
    <visual>
      <origin xyz="0 0 0" rpy="0 0 0"/>
      <geometry>
        <box size="${IMU_LEN} ${IMU_WID} ${IMU_HIG}"/>
      </geometry>
      <material name="mid_dark"/>
    </visual>

    <collision>
      <origin xyz="0 0 0" rpy="0 0 0"/>
      <geometry>
        <box size="${IMU_LEN} ${IMU_WID} ${IMU_HIG}"/>
      </geometry>
    </collision>

    <inertial>
      <mass value="${IMU_MASS}"/>
      <origin xyz="0 0 0" rpy="0 0 0"/>
      <inertia
        ixx="${IMU_MASS/12.0 * (IMU_WID*IMU_WID + IMU_HIG*IMU_HIG)}"
        iyy="${IMU_MASS/12.0 * (IMU_LEN*IMU_LEN + IMU_HIG*IMU_HIG)}"
        izz="${IMU_MASS/12.0 * (IMU_LEN*IMU_LEN + IMU_WID*IMU_WID)}"
        ixy="0" ixz="0" iyz="0"
      />
    </inertial>
  </link>


  

  <!-- <link name="base_link_gps">
    <visual>
      <origin xyz="0 0 0" rpy="0 0 0"/>
      <geometry>
        <cylinder radius="${GPS_ANTENNA_RAD}" length="${GPS_ANTENNA_HIG}"/>
      </geometry>
      <material name="white"/>
    </visual>
    
    <collision>
      <origin xyz="0 0 0" rpy="0 0 0"/>
      <geometry>
        <cylinder radius="${GPS_ANTENNA_RAD}" length="${GPS_ANTENNA_HIG}"/>
      </geometry>
    </collision>
    
    <inertial>
      <mass value="${GPS_ANTENNA_MASS}"/>
      <origin xyz="0 0 0" rpy="0 0 0"/>
      <inertia
        ixx="${0.5*GPS_ANTENNA_MASS*GPS_ANTENNA_HIG*GPS_ANTENNA_HIG}"
        iyy="${(1.0/12.0)*GPS_ANTENNA_MASS*(3*GPS_ANTENNA_RAD*GPS_ANTENNA_RAD + GPS_ANTENNA_HIG*GPS_ANTENNA_HIG)}"
        izz="${(1.0/12.0)*GPS_ANTENNA_MASS*(3*GPS_ANTENNA_RAD*GPS_ANTENNA_RAD + GPS_ANTENNA_HIG*GPS_ANTENNA_HIG)}"
        ixy="0.0" ixz="0.0" iyz="0.0"
      />
    </inertial>
  </link> -->

<!-- 
  <link name="vms_base">
    <visual>
      <origin xyz="0 0 0" rpy="0 0 0"/>
      <geometry>
        <box size="${VMS_LEN} ${VMS_WID} ${VMS_HIG}"/>
      </geometry>
      <material name="dark"/>
    </visual>
    
    <collision>
      <origin xyz="0 0 0" rpy="0 0 0"/>
      <geometry>
        <box size="${VMS_LEN} ${VMS_WID} ${VMS_HIG}"/>
      </geometry>
    </collision>
    
    <inertial>
      <mass value="${VMS_MASS}"/>
      <origin xyz="0 0 0" rpy="0 0 0"/>
      <inertia
        ixx="${VMS_MASS/12.0 * (VMS_WID*VMS_WID + VMS_HIG*VMS_HIG)}"
        iyy="${VMS_MASS/12.0 * (VMS_LEN*VMS_LEN + VMS_HIG*VMS_HIG)}"
        izz="${VMS_MASS/12.0 * (VMS_LEN*VMS_LEN + VMS_WID*VMS_WID)}"
        ixy="0.0" ixz="0.0" iyz="0.0"/>
    </inertial>
  </link>
  
  
  <link name="vms_cylinder">
    <visual>
      <origin xyz="0 0 0" rpy="${PI/2} 0 0"/>
      <geometry>
        <cylinder radius="${VMS_CYLINDER_RAD}" length="${VMS_CYLINDER_WID}"/>
      </geometry>
      <material name="dark"/>
    </visual>
     
    <collision>
      <origin xyz="0 0 0" rpy="${PI/2} 0 0"/>
      <geometry>
        <cylinder radius="${VMS_CYLINDER_RAD}" length="${VMS_CYLINDER_WID}"/>
      </geometry>
    </collision>
     
    <inertial>
      <mass value="${VMS_CYLINDER_MASS}"/>
      <origin xyz="0 0 0" rpy="${PI/2} 0 0"/>
      <inertia 
        ixx="${0.5*VMS_CYLINDER_MASS*VMS_CYLINDER_RAD*VMS_CYLINDER_RAD}"
        iyy="${(1.0/12.0)*VMS_CYLINDER_MASS*(3*VMS_CYLINDER_RAD*VMS_CYLINDER_RAD + VMS_CYLINDER_WID*VMS_CYLINDER_WID)}"
        izz="${(1.0/12.0)*VMS_CYLINDER_MASS*(3*VMS_CYLINDER_RAD*VMS_CYLINDER_RAD + VMS_CYLINDER_WID*VMS_CYLINDER_WID)}"
        ixy="0.0" ixz="0.0" iyz="0.0"/>
    </inertial>
  </link>
  
  
  
  <link name="vms_cylinder_base_left">
    <visual>
      <origin xyz="0 0 0" rpy="0 0 0"/>
      <geometry>
        <box size="${VMS_CYLINDER_BASE_LEN} ${VMS_CYLINDER_BASE_WID} ${VMS_CYLINDER_BASE_HIG}"/>
      </geometry>
      <material name="dark"/>
    </visual>
    
    <collision>
      <origin xyz="0 0 0" rpy="0 0 0"/>
      <geometry>
        <box size="${VMS_CYLINDER_BASE_LEN} ${VMS_CYLINDER_BASE_WID} ${VMS_CYLINDER_BASE_HIG}"/>
      </geometry>
    </collision>
    
    <inertial>
      <mass value="${VMS_CYLINDER_BASE_MASS}"/>
      <origin xyz="0 0 0" rpy="0 0 0"/>
      <inertia
        ixx="${VMS_CYLINDER_BASE_MASS/12.0 * (VMS_CYLINDER_BASE_WID*VMS_CYLINDER_BASE_WID + VMS_CYLINDER_BASE_HIG*VMS_CYLINDER_BASE_HIG)}"
        iyy="${VMS_CYLINDER_BASE_MASS/12.0 * (VMS_CYLINDER_BASE_LEN*VMS_CYLINDER_BASE_LEN + VMS_CYLINDER_BASE_HIG*VMS_CYLINDER_BASE_HIG)}"
        izz="${VMS_CYLINDER_BASE_MASS/12.0 * (VMS_CYLINDER_BASE_LEN*VMS_CYLINDER_BASE_LEN + VMS_CYLINDER_BASE_WID*VMS_CYLINDER_BASE_WID)}"
        ixy="0" ixz="0" iyz="0"
      />
    </inertial>
  </link>
  
  <link name="vms_cylinder_base_right">
    <visual>
      <origin xyz="0 0 0" rpy="0 0 0"/>
      <geometry>
        <box size="${VMS_CYLINDER_BASE_LEN} ${VMS_CYLINDER_BASE_WID} ${VMS_CYLINDER_BASE_HIG}"/>
      </geometry>
      <material name="dark"/>
    </visual>
    
    <collision>
      <origin xyz="0 0 0" rpy="0 0 0"/>
      <geometry>
        <box size="${VMS_CYLINDER_BASE_LEN} ${VMS_CYLINDER_BASE_WID} ${VMS_CYLINDER_BASE_HIG}"/>
      </geometry>
    </collision>
    
    <inertial>
      <mass value="${VMS_CYLINDER_BASE_MASS}"/>
      <origin xyz="0 0 0" rpy="0 0 0"/>
      <inertia
        ixx="${VMS_CYLINDER_BASE_MASS/12.0 * (VMS_CYLINDER_BASE_WID*VMS_CYLINDER_BASE_WID + VMS_CYLINDER_BASE_HIG*VMS_CYLINDER_BASE_HIG)}"
        iyy="${VMS_CYLINDER_BASE_MASS/12.0 * (VMS_CYLINDER_BASE_LEN*VMS_CYLINDER_BASE_LEN + VMS_CYLINDER_BASE_HIG*VMS_CYLINDER_BASE_HIG)}"
        izz="${VMS_CYLINDER_BASE_MASS/12.0 * (VMS_CYLINDER_BASE_LEN*VMS_CYLINDER_BASE_LEN + VMS_CYLINDER_BASE_WID*VMS_CYLINDER_BASE_WID)}"
        ixy="0" ixz="0" iyz="0"
      />
    </inertial>
  </link>
  
  
   
   
  
  <link name="vms_camera">
    <visual>
    <origin xyz="0 0 0" rpy="0 0 0"/>
      <geometry>
        <box size="${CAMERA_LEN} ${CAMERA_WID} ${CAMERA_HIG}"/>
      </geometry>
      <material name="mid_dark"/>
    </visual>
  
    <collision>
      <origin xyz="0 0 0" rpy="0 0 0"/>
      <geometry>
        <box size="${CAMERA_LEN} ${CAMERA_WID} ${CAMERA_HIG}"/>
      </geometry>
    </collision>
    
    <inertial>
      <mass value="${CAMERA_MASS}"/>
      <origin xyz="0 0 0" rpy="0 0 0"/>
      <inertia
        ixx="${CAMERA_MASS/12.0 * (CAMERA_WID*CAMERA_WID + CAMERA_HIG*CAMERA_HIG)}"
        iyy="${CAMERA_MASS/12.0 * (CAMERA_LEN*CAMERA_LEN + CAMERA_HIG*CAMERA_HIG)}"
        izz="${CAMERA_MASS/12.0 * (CAMERA_LEN*CAMERA_LEN + CAMERA_WID*CAMERA_WID)}"
        ixy="0" ixz="0" iyz="0"
      />
    </inertial>
  </link>
  
  <link name="vms_left_camera_yaw_link"/>

  <link name="vms_left_camera">
    <visual>
      <origin xyz="0 0 0" rpy="0 0 0"/>
      <geometry>
        <box size="${CAMERA_LEN} ${CAMERA_WID} ${CAMERA_HIG}"/>
      </geometry>
      <material name="mid_dark"/>
    </visual>
  
    <collision>
      <origin xyz="0 0 0" rpy="0 0 0"/>
      <geometry>
        <box size="${CAMERA_LEN} ${CAMERA_WID} ${CAMERA_HIG}"/>
      </geometry>
    </collision>
    
    <inertial>
      <mass value="${CAMERA_MASS}"/>
      <origin xyz="0 0 0" rpy="0 0 0"/>
      <inertia
        ixx="${CAMERA_MASS/12.0 * (CAMERA_WID*CAMERA_WID + CAMERA_HIG*CAMERA_HIG)}"
        iyy="${CAMERA_MASS/12.0 * (CAMERA_LEN*CAMERA_LEN + CAMERA_HIG*CAMERA_HIG)}"
        izz="${CAMERA_MASS/12.0 * (CAMERA_LEN*CAMERA_LEN + CAMERA_WID*CAMERA_WID)}"
        ixy="0" ixz="0" iyz="0"
      />
    </inertial>
  </link>
      
      
  <link name="vms_back_camera">
    <visual>
      <origin xyz="0 0 0" rpy="0 0 0"/>
      <geometry>
        <box size="${CAMERA_LEN} ${CAMERA_WID} ${CAMERA_HIG}"/>
      </geometry>
      <material name="mid_dark"/>
    </visual>
  
    <collision>
      <origin xyz="0 0 0" rpy="0 0 0"/>
      <geometry>
        <box size="${CAMERA_LEN} ${CAMERA_WID} ${CAMERA_HIG}"/>
      </geometry>
    </collision>
    
    <inertial>
      <mass value="${CAMERA_MASS}"/>
      <origin xyz="0 0 0" rpy="0 0 0"/>
      <inertia
        ixx="${CAMERA_MASS/12.0 * (CAMERA_WID*CAMERA_WID + CAMERA_HIG*CAMERA_HIG)}"
        iyy="${CAMERA_MASS/12.0 * (CAMERA_LEN*CAMERA_LEN + CAMERA_HIG*CAMERA_HIG)}"
        izz="${CAMERA_MASS/12.0 * (CAMERA_LEN*CAMERA_LEN + CAMERA_WID*CAMERA_WID)}"
        ixy="0" ixz="0" iyz="0"
      />
    </inertial>
  </link>
  
  
  <link name="vms_gps">
    <visual>
      <origin xyz="0 0 0" rpy="0 0 0"/>
      <geometry>
        <cylinder radius="${GPS_ANTENNA_RAD}" length="${GPS_ANTENNA_HIG}"/>
      </geometry>
      <material name="white"/>
    </visual>
    
    <collision>
      <origin xyz="0 0 0" rpy="0 0 0"/>
      <geometry>
        <cylinder radius="${GPS_ANTENNA_RAD}" length="${GPS_ANTENNA_HIG}"/>
      </geometry>
    </collision>
    
    <inertial>
      <mass value="${GPS_ANTENNA_MASS}"/>
      <origin xyz="0 0 0" rpy="0 0 0"/>
      <inertia
        ixx="${0.5*GPS_ANTENNA_MASS*GPS_ANTENNA_HIG*GPS_ANTENNA_HIG}"
        iyy="${(1.0/12.0)*GPS_ANTENNA_MASS*(3*GPS_ANTENNA_RAD*GPS_ANTENNA_RAD + GPS_ANTENNA_HIG*GPS_ANTENNA_HIG)}"
        izz="${(1.0/12.0)*GPS_ANTENNA_MASS*(3*GPS_ANTENNA_RAD*GPS_ANTENNA_RAD + GPS_ANTENNA_HIG*GPS_ANTENNA_HIG)}"
        ixy="0.0" ixz="0.0" iyz="0.0"
      />
    </inertial>
  </link>
  
  
  
   -->
  
  <link name="front_lidar">
    <visual>
      <origin xyz="0 0 0" rpy="0 0 0"/>
      <geometry>
        <cylinder radius="${LIDAR_RAD}" length="${LIDAR_HIG}"/>
      </geometry>
      <material name="blue_green"/>
    </visual> 
  
    <collision>
      <origin xyz="0 0 0" rpy="0 0 0"/>
      <geometry>
        <cylinder radius="${LIDAR_RAD}" length="${LIDAR_HIG}"/>
      </geometry>
    </collision>
    
    <inertial>
      <mass value="${LIDAR_MASS}"/>
      <origin xyz="0 0 0" rpy="0 0 0"/>
      <inertia
        ixx="${0.5*LIDAR_MASS*LIDAR_HIG*LIDAR_HIG}"
        iyy="${(1.0/12.0)*LIDAR_MASS*(3*LIDAR_RAD*LIDAR_RAD + LIDAR_HIG*LIDAR_HIG)}"
        izz="${(1.0/12.0)*LIDAR_MASS*(3*LIDAR_RAD*LIDAR_RAD + LIDAR_HIG*LIDAR_HIG)}"
        ixy="0.0" ixz="0.0" iyz="0.0"
      />
    </inertial>
  </link>
  
  
  <!-- <link name="back_lidar">
    <visual>
      <origin xyz="0 0 0" rpy="0 0 0"/>
      <geometry>
        <cylinder radius="${LIDAR_RAD}" length="${LIDAR_HIG}"/>
      </geometry>
      <material name="blue_green"/>
    </visual> 
  
    <collision>
      <origin xyz="0 0 0" rpy="0 0 0"/>
      <geometry>
        <cylinder radius="${LIDAR_RAD}" length="${LIDAR_HIG}"/>
      </geometry>
    </collision>
    
    <inertial>
      <mass value="${LIDAR_MASS}"/>
      <origin xyz="0 0 0" rpy="0 0 0"/>
      <inertia
        ixx="${0.5*LIDAR_MASS*LIDAR_HIG*LIDAR_HIG}"
        iyy="${(1.0/12.0)*LIDAR_MASS*(3*LIDAR_RAD*LIDAR_RAD + LIDAR_HIG*LIDAR_HIG)}"
        izz="${(1.0/12.0)*LIDAR_MASS*(3*LIDAR_RAD*LIDAR_RAD + LIDAR_HIG*LIDAR_HIG)}"
        ixy="0.0" ixz="0.0" iyz="0.0"
      />
    </inertial>
  </link>
   -->
  
  <!--  ***라이다와 라이다 베이스 같이 있을 시 tf 복잡하여 주석 처리.***
  <link name="front_lidar_base">
    <visual>
      <origin xyz="0 0 0" rpy="0 0 0"/>
      <geometry>
        <box size="${LIDAR_BASE_LEN} ${LIDAR_BASE_WID} ${LIDAR_BASE_HIG}"/>
      </geometry>
      <material name="mid_dark"/>
    </visual>
    
    <collision>
      <origin xyz="0 0 0" rpy="0 0 0"/>
      <geometry>
        <box size="${LIDAR_BASE_LEN} ${LIDAR_BASE_WID} ${LIDAR_BASE_HIG}"/>
      </geometry>
    </collision>
    
    <inertial>
      <mass value="${LIDAR_BASE_MASS}"/>
      <origin xyz="0 0 0" rpy="0 0 0"/>
      <inertia
        ixx="${LIDAR_BASE_MASS/12.0 * (LIDAR_BASE_WID*LIDAR_BASE_WID + LIDAR_BASE_HIG*LIDAR_BASE_HIG)}"
        iyy="${LIDAR_BASE_MASS/12.0 * (LIDAR_BASE_LEN*LIDAR_BASE_LEN + LIDAR_BASE_HIG*LIDAR_BASE_HIG)}"
        izz="${LIDAR_BASE_MASS/12.0 * (LIDAR_BASE_LEN*LIDAR_BASE_LEN + LIDAR_BASE_WID*LIDAR_BASE_WID)}"
        ixy="0.0" ixz="0.0" iyz="0.0"/>
    </inertial>
  </link>
      

  <link name="back_lidar_base">
    <visual>
      <origin xyz="0 0 0" rpy="0 0 0"/>
      <geometry>
        <box size="${LIDAR_BASE_LEN} ${LIDAR_BASE_WID} ${LIDAR_BASE_HIG}"/>
      </geometry>
      <material name="mid_dark"/>
    </visual>
    
    <collision>
      <origin xyz="0 0 0" rpy="0 0 0"/>
      <geometry>
        <box size="${LIDAR_BASE_LEN} ${LIDAR_BASE_WID} ${LIDAR_BASE_HIG}"/>
      </geometry>
    </collision>
    
    <inertial>
      <mass value="${LIDAR_BASE_MASS}"/>
      <origin xyz="0 0 0" rpy="0 0 0"/>
      <inertia
        ixx="${LIDAR_BASE_MASS/12.0 * (LIDAR_BASE_WID*LIDAR_BASE_WID + LIDAR_BASE_HIG*LIDAR_BASE_HIG)}"
        iyy="${LIDAR_BASE_MASS/12.0 * (LIDAR_BASE_LEN*LIDAR_BASE_LEN + LIDAR_BASE_HIG*LIDAR_BASE_HIG)}"
        izz="${LIDAR_BASE_MASS/12.0 * (LIDAR_BASE_LEN*LIDAR_BASE_LEN + LIDAR_BASE_WID*LIDAR_BASE_WID)}"
        ixy="0.0" ixz="0.0" iyz="0.0"/>
    </inertial>
  </link>
  -->
  
  
  
  
  <!--  ***라이다 베이스와 마찬가지 이유로 주석 처리***
  <link name="front_left_wheel_base">
    <visual>
      <origin xyz="0 0 0" rpy="0 0 0"/>
      <geometry>
        <box size="${WHEEL_BASE_LEN} ${WHEEL_BASE_WID} ${WHEEL_BASE_HIG}"/>
      </geometry>
      <material name="dark"/>
    </visual>
    
    <collision>
      <origin xyz="0 0 0" rpy="0 0 0"/>
      <geometry>
        <box size="${WHEEL_BASE_LEN} ${WHEEL_BASE_WID} ${WHEEL_BASE_HIG}"/>
      </geometry>
    </collision>
    
    <inertial>
      <mass value="${WHEEL_BASE_MASS}"/>
      <origin xyz="0 0 0" rpy="0 0 0"/>
      <inertia
        ixx="${WHEEL_BASE_MASS/12.0 * (WHEEL_BASE_WID*WHEEL_BASE_WID + WHEEL_BASE_HIG*WHEEL_BASE_HIG)}"
        iyy="${WHEEL_BASE_MASS/12.0 * (WHEEL_BASE_LEN*WHEEL_BASE_LEN + WHEEL_BASE_HIG*WHEEL_BASE_HIG)}"
        izz="${WHEEL_BASE_MASS/12.0 * (WHEEL_BASE_LEN*WHEEL_BASE_LEN + WHEEL_BASE_WID*WHEEL_BASE_WID)}"
        ixy="0.0" ixz="0.0" iyz="0.0"/>
    </inertial>
  </link>
  
  
  <link name="front_right_wheel_base">
    <visual>
      <origin xyz="0 0 0" rpy="0 0 0"/>
      <geometry>
        <box size="${WHEEL_BASE_LEN} ${WHEEL_BASE_WID} ${WHEEL_BASE_HIG}"/>
      </geometry>
      <material name="dark"/>
    </visual>
    
    <collision>
      <origin xyz="0 0 0" rpy="0 0 0"/>
      <geometry>
        <box size="${WHEEL_BASE_LEN} ${WHEEL_BASE_WID} ${WHEEL_BASE_HIG}"/>
      </geometry>
    </collision>
    
    <inertial>
      <mass value="${WHEEL_BASE_MASS}"/>
      <origin xyz="0 0 0" rpy="0 0 0"/>
      <inertia
        ixx="${WHEEL_BASE_MASS/12.0 * (WHEEL_BASE_WID*WHEEL_BASE_WID + WHEEL_BASE_HIG*WHEEL_BASE_HIG)}"
        iyy="${WHEEL_BASE_MASS/12.0 * (WHEEL_BASE_LEN*WHEEL_BASE_LEN + WHEEL_BASE_HIG*WHEEL_BASE_HIG)}"
        izz="${WHEEL_BASE_MASS/12.0 * (WHEEL_BASE_LEN*WHEEL_BASE_LEN + WHEEL_BASE_WID*WHEEL_BASE_WID)}"
        ixy="0.0" ixz="0.0" iyz="0.0"/>
    </inertial>
  </link>
  
  
  <link name="back_left_wheel_base">
    <visual>
      <origin xyz="0 0 0" rpy="0 0 0"/>
      <geometry>
        <box size="${WHEEL_BASE_LEN} ${WHEEL_BASE_WID} ${WHEEL_BASE_HIG}"/>
      </geometry>
      <material name="dark"/>
    </visual>
    
    <collision>
      <origin xyz="0 0 0" rpy="0 0 0"/>
      <geometry>
        <box size="${WHEEL_BASE_LEN} ${WHEEL_BASE_WID} ${WHEEL_BASE_HIG}"/>
      </geometry>
    </collision>
    
    <inertial>
      <mass value="${WHEEL_BASE_MASS}"/>
      <origin xyz="0 0 0" rpy="0 0 0"/>
      <inertia
        ixx="${WHEEL_BASE_MASS/12.0 * (WHEEL_BASE_WID*WHEEL_BASE_WID + WHEEL_BASE_HIG*WHEEL_BASE_HIG)}"
        iyy="${WHEEL_BASE_MASS/12.0 * (WHEEL_BASE_LEN*WHEEL_BASE_LEN + WHEEL_BASE_HIG*WHEEL_BASE_HIG)}"
        izz="${WHEEL_BASE_MASS/12.0 * (WHEEL_BASE_LEN*WHEEL_BASE_LEN + WHEEL_BASE_WID*WHEEL_BASE_WID)}"
        ixy="0.0" ixz="0.0" iyz="0.0"/>
    </inertial>
  </link>
  
  
  <link name="back_right_wheel_base">
    <visual>
      <origin xyz="0 0 0" rpy="0 0 0"/>
      <geometry>
        <box size="${WHEEL_BASE_LEN} ${WHEEL_BASE_WID} ${WHEEL_BASE_HIG}"/>
      </geometry>
      <material name="dark"/>
    </visual>
    
    <collision>
      <origin xyz="0 0 0" rpy="0 0 0"/>
      <geometry>
        <box size="${WHEEL_BASE_LEN} ${WHEEL_BASE_WID} ${WHEEL_BASE_HIG}"/>
      </geometry>
    </collision>
    
    <inertial>
      <mass value="${WHEEL_BASE_MASS}"/>
      <origin xyz="0 0 0" rpy="0 0 0"/>
      <inertia
        ixx="${WHEEL_BASE_MASS/12.0 * (WHEEL_BASE_WID*WHEEL_BASE_WID + WHEEL_BASE_HIG*WHEEL_BASE_HIG)}"
        iyy="${WHEEL_BASE_MASS/12.0 * (WHEEL_BASE_LEN*WHEEL_BASE_LEN + WHEEL_BASE_HIG*WHEEL_BASE_HIG)}"
        izz="${WHEEL_BASE_MASS/12.0 * (WHEEL_BASE_LEN*WHEEL_BASE_LEN + WHEEL_BASE_WID*WHEEL_BASE_WID)}"
        ixy="0.0" ixz="0.0" iyz="0.0"/>
    </inertial>
  </link>
  -->
  
  
  
  
  
  <link name="front_left_wheel">
    <visual>
      <origin xyz="0 0 0" rpy="${PI/2} 0 0"/>
      <geometry>
        <cylinder radius="${WHEEL_RAD}" length="${WHEEL_WID}"/>
      </geometry>
      <material name="gray"/>
    </visual>
    
    <collision>
      <origin xyz="0 0 0" rpy="${PI/2} 0 0"/>
      <geometry>
        <cylinder radius="${WHEEL_RAD}" length="${WHEEL_WID}"/>
      </geometry>
    </collision>
    
    <inertial>
      <mass value="${WHEEL_MASS}"/>
      <origin xyz="0 0 0" rpy="${PI/2} 0 0"/>
      <inertia 
        ixx="${0.5*WHEEL_MASS*WHEEL_RAD*WHEEL_RAD}"
        iyy="${(1.0/12.0)*WHEEL_MASS*(3*WHEEL_RAD*WHEEL_RAD + WHEEL_WID*WHEEL_WID)}"
        izz="${(1.0/12.0)*WHEEL_MASS*(3*WHEEL_RAD*WHEEL_RAD + WHEEL_WID*WHEEL_WID)}"
        ixy="0.0" ixz="0.0" iyz="0.0"
      />
    </inertial>
  </link>
  
  
  <link name="back_left_wheel">
    <visual>
      <origin xyz="0 0 0" rpy="${PI/2} 0 0"/>
      <geometry>
        <cylinder radius="${WHEEL_RAD}" length="${WHEEL_WID}"/>
      </geometry>
      <material name="gray"/>
    </visual>
    
    <collision>
      <origin xyz="0 0 0" rpy="${PI/2} 0 0"/>
      <geometry>
        <cylinder radius="${WHEEL_RAD}" length="${WHEEL_WID}"/>
      </geometry>
    </collision>
    
    <inertial>
      <mass value="${WHEEL_MASS}"/>
      <origin xyz="0 0 0" rpy="${PI/2} 0 0"/>
      <inertia 
        ixx="${0.5*WHEEL_MASS*WHEEL_RAD*WHEEL_RAD}"
        iyy="${(1.0/12.0)*WHEEL_MASS*(3*WHEEL_RAD*WHEEL_RAD + WHEEL_WID*WHEEL_WID)}"
        izz="${(1.0/12.0)*WHEEL_MASS*(3*WHEEL_RAD*WHEEL_RAD + WHEEL_WID*WHEEL_WID)}"
        ixy="0.0" ixz="0.0" iyz="0.0"
      />
    </inertial>
  </link>
  
  
  <link name="front_right_wheel">
    <visual>
      <origin xyz="0 0 0" rpy="${PI/2} 0 0"/>
      <geometry>
        <cylinder radius="${WHEEL_RAD}" length="${WHEEL_WID}"/>
      </geometry>
      <material name="gray"/>
    </visual>
    
    <collision>
      <origin xyz="0 0 0" rpy="${PI/2} 0 0"/>
      <geometry>
        <cylinder radius="${WHEEL_RAD}" length="${WHEEL_WID}"/>
      </geometry>
    </collision>
    
    <inertial>
      <mass value="${WHEEL_MASS}"/>
      <origin xyz="0 0 0" rpy="${PI/2} 0 0"/>
      <inertia 
        ixx="${0.5*WHEEL_MASS*WHEEL_RAD*WHEEL_RAD}"
        iyy="${(1.0/12.0)*WHEEL_MASS*(3*WHEEL_RAD*WHEEL_RAD + WHEEL_WID*WHEEL_WID)}"
        izz="${(1.0/12.0)*WHEEL_MASS*(3*WHEEL_RAD*WHEEL_RAD + WHEEL_WID*WHEEL_WID)}"
        ixy="0.0" ixz="0.0" iyz="0.0"
      />
    </inertial>
  </link>
  
  
  <link name="back_right_wheel">
    <visual>
      <origin xyz="0 0 0" rpy="${PI/2} 0 0"/>
      <geometry>
        <cylinder radius="${WHEEL_RAD}" length="${WHEEL_WID}"/>
      </geometry>
      <material name="gray"/>
    </visual>
    
    <collision>
      <origin xyz="0 0 0" rpy="${PI/2} 0 0"/>
      <geometry>
        <cylinder radius="${WHEEL_RAD}" length="${WHEEL_WID}"/>
      </geometry>
    </collision>
    
    <inertial>
      <mass value="${WHEEL_MASS}"/>
      <origin xyz="0 0 0" rpy="${PI/2} 0 0"/>
      <inertia 
        ixx="${0.5*WHEEL_MASS*WHEEL_RAD*WHEEL_RAD}"
        iyy="${(1.0/12.0)*WHEEL_MASS*(3*WHEEL_RAD*WHEEL_RAD + WHEEL_WID*WHEEL_WID)}"
        izz="${(1.0/12.0)*WHEEL_MASS*(3*WHEEL_RAD*WHEEL_RAD + WHEEL_WID*WHEEL_WID)}"
        ixy="0.0" ixz="0.0" iyz="0.0"
      />
    </inertial>
  </link>
  
  
  
  


  <!-- base_link는 지면 좌표, base_chassis 지면으로부터 떨어져 있는 실제 로봇 몸통 중심 높이(바퀴 크기 + 로봇 몸통 중간-->
  <joint name="base_joint" type="fixed">
    <origin xyz="0 0 ${BASE_HIG/2 +WHEEL_RAD*2}" rpy="0 0 0"/>
    <parent link="base_link"/>
    <child link="base_chassis"/>
  </joint> 


  <joint name="imu_joint" type="fixed">
    <origin xyz="${BASE_LEN/2 - IMU_X_SEP} 0 ${IMU_HIG/2}" rpy="0 0 0"/>
    <parent link="base_chassis"/>
    <child link="imu"/>
  </joint>


  <!--
  좌/우 베이스: y=±(실린더 길이/2), z는 베이스 높이 맞춤
  좌/우 베이스 고정
  <joint name="vms_cylinder_base_joint_left" type="fixed">
    <origin xyz="${BASE_LEN/2 - VMS_CYLINDER_X_LEN} ${ VMS_CYLINDER_WID/2} ${BASE_HIG/2 + VMS_CYLINDER_BASE_HIG/2}" rpy="0 0 0"/>
    <parent link="base_chassis"/>
    <child  link="vms_cylinder_base_left"/>
  </joint>

  <joint name="vms_cylinder_base_joint_right" type="fixed">
    <origin xyz="${BASE_LEN/2 - VMS_CYLINDER_X_LEN} ${-VMS_CYLINDER_WID/2} ${BASE_HIG/2 + VMS_CYLINDER_BASE_HIG/2}" rpy="0 0 0"/>
    <parent link="base_chassis"/>
    <child  link="vms_cylinder_base_right"/>
  </joint>

  힌지도 같은 x/z로
  <joint name="vms_cylinder_joint" type="fixed">
    <origin xyz="${BASE_LEN/2 - VMS_CYLINDER_X_LEN} 0 ${BASE_HIG/2 + VMS_CYLINDER_BASE_HIG/2}" rpy="0 ${PI/2} 0"/>
    <parent link="base_chassis"/>
    <child  link="vms_cylinder"/>
  </joint>
  
  <joint name="vms_joint" type="fixed">
    <origin xyz="${-VMS_LEN/2} 0 ${VMS_CYLINDER_BASE_HIG/2}" rpy="0 0 0"/>
    <parent link="vms_cylinder"/>
    <child  link="vms_base"/>
  </joint>
    
  
  
  VMS 카메라
  <joint name="vms_camera_joint" type="fixed">
    <origin xyz="-${VMS_LEN/2 - CAMERA_X_LEN} 0 ${VMS_HIG/2 + CAMERA_HIG/2}" rpy="0 -${90*PI/180} 0"/>
    <parent link="vms_base"/>
    <child link="vms_camera"/>
  </joint>
  
  [1] 위치 이동 + YAW=+45°를 먼저 적용
  <joint name="vms_left_camera_yaw_joint" type="fixed">
    <origin
      xyz="-${VMS_LEN/2 + CAMERA_HIG/2} -${VMS_WID/2 - LEFT_CAMERA_Y_LEN} 0" rpy="${45*PI/180} 0 0"/>
    <parent link="vms_base"/>
    <child  link="vms_left_camera_yaw_link"/>
  </joint>
  
  [2] 그 다음 PITCH/ROLL만 적용 (예: 좌측을 바라보게 pitch=-90°)
  <joint name="vms_left_camera_joint" type="fixed">
    <origin xyz="0 0 0" rpy="0 -${90*PI/180} 0"/>
    <parent link="vms_left_camera_yaw_link"/>
    <child  link="vms_left_camera"/>
  </joint>
 
 
  <joint name="vms_back_camera_joint" type="fixed">
    <origin xyz="-${VMS_LEN/2 - BACK_CAMERA_X_LEN} 0 -${VMS_HIG/2 + CAMERA_HIG/2}" rpy="-${180*PI/180} ${90*PI/180} 0"/>
    <parent link="vms_base"/>
    <child link="vms_back_camera"/>
  </joint>
 
 
  VMS GPS
  <joint name="vms_gps_joint" type="fixed">
    <origin xyz="-${VMS_LEN/2 + GPS_ANTENNA_HIG/2} 0 0" rpy="0 -${PI/2} 0"/>
    <parent link="vms_base"/>
    <child link="vms_gps"/>
  </joint>
  
   -->
  
  <!-- 몸통 GPS -->
  <!-- <joint name="base_link_gps_joint" type="fixed">
    <origin xyz="-${BASE_LEN/2 - BASE_GPS_ANTENNA_SEP} 0 ${BASE_HIG/2}" rpy="0 0 0"/>
    <parent link="base_chassis"/>
    <child link="base_link_gps"/>    
  </joint> -->


  <!--바퀴 -->	
  <joint name="front_left_wheel_joint" type="continuous">
    <origin xyz="${WHEEL_LEN_SEP/2} ${WHEEL_WID_SEP/2} ${-(WHEEL_RAD + BASE_HIG/2)}" rpy="0 0 0"/>
    <parent link="base_chassis"/>
    <child link="front_left_wheel"/>
    <axis xyz="0 1 0"/>
  </joint>
     
  <joint name="back_left_wheel_joint" type="continuous">
    <origin xyz="-${WHEEL_LEN_SEP/2} ${WHEEL_WID_SEP/2} ${-(WHEEL_RAD+ BASE_HIG/2)}" rpy="0 0 0"/>
    <parent link="base_chassis"/>
    <child link="back_left_wheel"/>
    <axis xyz="0 1 0"/>
  </joint>
  
  <joint name="front_right_wheel_joint" type="continuous">
    <origin xyz="${WHEEL_LEN_SEP/2} -${WHEEL_WID_SEP/2} ${-(WHEEL_RAD + BASE_HIG/2)}" rpy="0 0 0"/>
    <parent link="base_chassis"/>
    <child link="front_right_wheel"/>
    <axis xyz="0 1 0"/>
  </joint>

  <joint name="back_right_wheel_joint" type="continuous">
    <origin xyz="-${WHEEL_LEN_SEP/2} -${WHEEL_WID_SEP/2} ${-(WHEEL_RAD + BASE_HIG/2)}" rpy="0 0 0"/>
    <parent link="base_chassis"/>
    <child link="back_right_wheel"/>
    <axis xyz="0 1 0"/>
  </joint>
  
  
  <!--바퀴 베이스-->
  <!--
  <joint name="front_left_wheel_base_joint" type="fixed">
    <origin xyz="${WHEEL_LEN_SEP/2} ${WHEEL_WID_SEP/2} ${-(BASE_HIG/2 + WHEEL_BASE_HIG/2)}" rpy="0 0 0"/>
    <parent link="base_chassis"/>
    <child link="front_left_wheel_base"/>
  </joint> 
  
  
  <joint name="front_right_wheel_base_joint" type="fixed">
    <origin xyz="${WHEEL_LEN_SEP/2} -${WHEEL_WID_SEP/2} ${-(BASE_HIG/2 + WHEEL_BASE_HIG/2)}" rpy="0 0 0"/>
    <parent link="base_chassis"/>
    <child link="front_right_wheel_base"/>
  </joint>
 
  
  <joint name="back_left_wheel_base_joint" type="fixed">
    <origin xyz="-${WHEEL_LEN_SEP/2} ${WHEEL_WID_SEP/2} ${-(BASE_HIG/2 + WHEEL_BASE_HIG/2)}" rpy="0 0 0"/>
    <parent link="base_chassis"/>
    <child link="back_left_wheel_base"/>
  </joint>
 
  
  
  <joint name="back_right_wheel_base_joint" type="fixed">
    <origin xyz="-${WHEEL_LEN_SEP/2} -${WHEEL_WID_SEP/2} ${-(BASE_HIG/2 + WHEEL_BASE_HIG/2)}" rpy="0 0 0"/>
    <parent link="base_chassis"/>
    <child link="back_right_wheel_base"/>
  </joint>
  -->
  
  
  <!-- 라이다 -->
  <joint name="front_lidar_joint" type="fixed">
    <!-- <origin xyz="${BASE_LEN/2 - F_LIDAR_SEP_LEN} -${BASE_WID/2 - F_LIDAR_SEP_WID} ${BASE_HIG/2 + LIDAR_HIG/2}" rpy="0 ${17*PI/180} 0"/> 라이다만 17도로 변경하기라이다만 17도로 변경하기 -->
    <origin xyz="0 0 ${BASE_HIG/2 + LIDAR_HIG/2}" rpy="0 0 0"/> <!-- wall_pilot을 위해 기울기 0도로 수정 -->
    <parent link="base_chassis"/>
    <child link="front_lidar"/>
  </joint>
  
  <!-- <joint name="back_lidar_joint" type="fixed">
    <origin xyz="-${BASE_LEN/2 - B_LIDAR_SEP_LEN} ${BASE_WID/2 - B_LIDAR_SEP_WID} ${BASE_HIG/2 + LIDAR_HIG/2}" rpy="0 ${17*PI/180} ${PI}"/> 라이다만 17도로 변경하기
    <origin xyz="-${BASE_LEN/2 - B_LIDAR_SEP_LEN} ${BASE_WID/2 - B_LIDAR_SEP_WID} ${BASE_HIG/2 + LIDAR_HIG/2}" rpy="0 0 ${PI}"/>
    <parent link="base_chassis"/>
    <child link="back_lidar"/>
  </joint> -->
  
  
  <!-- 라이다 베이스 주석처리 -->
  <!--
  <joint name="front_lidar_joint" type="fixed">
    <origin xyz="0 0 ${LIDAR_HIG/2}" rpy="0 ${17*PI/180} 0"/> 
    <parent link="front_lidar_base"/>
    <child link="front_lidar"/>
  </joint>
  
  <joint name="back_lidar_joint" type="fixed">
    <origin xyz="0 0 ${LIDAR_HIG/2}" rpy="0 ${17*PI/180} 0"/> 
    <parent link="back_lidar_base"/>
    <child link="back_lidar"/>
  </joint>
  
    
  
  <joint name="front_lidar_base_joint" type="fixed">
    <origin xyz="${BASE_LEN/2 - F_LIDAR_SEP_LEN} -${BASE_WID/2 - F_LIDAR_SEP_WID} ${BASE_HIG/2 + LIDAR_BASE_HIG/2}" rpy="0 0 0"/> 
    <parent link="base_chassis"/>
    <child link="front_lidar_base"/>
  </joint>
  
  
  <joint name="back_lidar_base_joint" type="fixed">
    <origin xyz="-${BASE_LEN/2 - B_LIDAR_SEP_LEN} ${BASE_WID/2 - B_LIDAR_SEP_WID} ${BASE_HIG/2 + LIDAR_BASE_HIG/2}" rpy="0 0 ${PI}"/>
    <parent link="base_chassis"/>
    <child link="back_lidar_base"/>
  </joint>
  -->

  <gazebo reference="base_link">
    <material>Gazebo/White</material>
  </gazebo>
<!--   
  <gazebo reference="vms_base">
    <material>Gazebo/Gray</material>
  </gazebo>
  
  <gazebo reference="vms_cylinder">
    <material>Gazebo/Gray</material> 
  </gazebo> -->
  
  <gazebo reference="front_left_wheel">
    <material>Gazebo/Black</material>
  </gazebo>
  <gazebo reference="back_left_wheel">
    <material>Gazebo/Black</material>
  </gazebo>
  <gazebo reference="front_right_wheel">
    <material>Gazebo/Black</material>
  </gazebo>
  <gazebo reference="back_right_wheel">
    <material>Gazebo/Black</material>
  </gazebo>
  
  
  <!-- <gazebo reference="front_left_wheel_base">
    <material>Gazebo/Black</material>
  </gazebo>
  <gazebo reference="front_right_wheel_base">
    <material>Gazebo/Black</material>
  </gazebo>
  <gazebo reference="back_left_wheel_base">
    <material>Gazebo/Black</material>
  </gazebo>
  <gazebo reference="back_right_wheel_base">
    <material>Gazebo/Black</material>
  </gazebo> -->

  <!-- <gazebo reference="vms_camera"> vms_left_camera에 카메라 센서 붙임
    <material>Gazebo/DarkGrey </material>
    <sensor name="camera" type="camera"> name = 센서의 고유 이름, type = 카메라 센서
      <always_on>1</always_on> 시뮬레이션 실행 시 항상 작동
      <update_rate>30.0</update_rate> 카메라 프레임 레이트 = 30
      
      <camera> 카메라의 시각적 특성 정의
        <horizontal_fov>1.047</horizontal_fov> 카메라 수평 시야 각

        <image> 이미지 출력 설정
          <width>640</width> 가로 해상도
          <height>480</height> 세로 해상도
          <format>R8G8B8</format> 출력 포맷 RGB 24bit
        </image>

        <clip> 시야 범위 설정
          <near>0.1</near> 0.1m 보다 가까운 것은 무시
          <far>100</far> 100미터 넘어가면 짤림
        </clip>
      </camera>
      <plugin name="camera_controller" filename="libgazebo_ros_camera.so">
        <ros>
          <namespace>/easyai</namespace>
          <remapping>image_raw:=vms_camera/image_raw</remapping>
          <remapping>camera_info:=vms_camera/camera_info</remapping>
        </ros>
        <frameName>vms_camera</frameName> 링크 이름과 같아야 함.
        <updateRate>30.0</updateRate>
      </plugin>
    </sensor>
  </gazebo>
  
  <gazebo reference="vms_left_camera"> 
    <material>Gazebo/DarkGrey </material>
    <sensor name="left_camera" type="camera"> 
      <always_on>1</always_on>
      <update_rate>30</update_rate> 
      <camera> 
        <horizontal_fov>1.047</horizontal_fov> 

        <image> 
          <width>640</width> 
          <height>480</height> 
          <format>R8G8B8</format> 
        </image>

        <clip> 
          <near>0.1</near> 
          <far>100</far> 
        </clip>
      </camera>
      <plugin name="left_camera_controller" filename="libgazebo_ros_camera.so">
        <ros>
          <namespace>/easyai</namespace>
          <remapping>image_raw:=vms_left_camera/image_raw</remapping>
          <remapping>camera_info:=vms_left_camera/camera_info</remapping>
        </ros>
        <frameName>vms_left_camera</frameName>
        <updateRate>30.0</updateRate>
      </plugin>
    </sensor>
  </gazebo>

  <gazebo reference="vms_back_camera">
    <material>Gazebo/Darkgray</material>
    <sensor name="back_camera" type="camera">
      <always_on>1</always_on>
      <update_rate>30.0</update_rate>
      <camera>
        <horizontal_fov>1.047</horizontal_fov>
        <image>
          <width>640</width>
          <height>480</height>
          <format>R8G8B8</format>
        </image>
        <clip>
          <near>0.1</near>
          <far>100</far>
        </clip>
      </camera>
      <plugin name="back_camera_controller" filename="libgazebo_ros_camera.so">
        <ros>
          <namespace>/easyai</namespace>
          <remapping>image_raw:=vms_back_camera/image_raw</remapping>
          <remapping>camera_info:=vms_back_camera/camera_info</remapping>
        </ros>
        <frameName>vms_back_camera</frameName>
        <updateRate>30.0</updateRate>
      </plugin>
    </sensor>
  </gazebo> -->
  
  <gazebo reference="front_lidar">
    <material>Gazebo/Darkgray</material>
    <sensor name="front_lidar_senser" type="ray">
      <visualize>true</visualize>
      <update_rate>10.0</update_rate>
      <ray>
        <scan>
          <horizontal>
            <samples>360</samples> <!-- 라이다 포인트 수 : 180개-->
            <resolution>1</resolution> <!-- 라이다 포인터 간 각도 : 1도-->
            <!-- <max_angle>3.14</max_angle> 왼쪽 100 도
            <min_angle>-3.14</min_angle>오른쪽 100도 -->
            <max_angle>3.14</max_angle>
            <min_angle>-3.14</min_angle>
          </horizontal> <!-- 라이다 범위 : 180도 , 포인트 수 : 180 , 포인터 간 각도 : 1도-->
        </scan>
        <range><!-- ydlidar 기준 0.12~10.0까지 가능 -->
          <min>0.2</min> <!-- 20cm부터-->
          <max>5.0</max> <!-- 5m까지 -->
        </range>
      </ray>
      <plugin name="front_lidar_controller" filename="libgazebo_ros_ray_sensor.so">
        <ros>

          <argument>~/out:=/scan</argument>
        </ros>
        <output_type>sensor_msgs/LaserScan</output_type>
        <frameName>front_lidar</frameName>
        <updateRate>10.0</updateRate>
      </plugin>
    </sensor>
  </gazebo>

  <!-- <gazebo reference="back_lidar">
    <material>Gazebo/Darkgray</material>
    <sensor name="back_lidar_senser" type="ray">
      <visualize>true</visualize>
      <update_rate>10.0</update_rate>
      <ray>
        <scan>
          <horizontal>
            <samples>200</samples>
            <resolution>1</resolution>
            <max_angle>-${100*PI/180}</max_angle>
            <min_angle>${100*PI/180}</min_angle>
          </horizontal>
        </scan>
        <range>
          <min>0.2</min>
          <max>5.0</max>
        </range>
      </ray>
    </sensor>
  </gazebo> -->
  <!--skid_steer_drive_controller-->
  <!-- 4륜차-->
  <gazebo>
    <plugin filename="libgazebo_ros_diff_drive.so" name="skid_steer_drive_controller"> <!-- 4륜차-->
      <ros>
        <namespace>/easyai</namespace>
        <remapping>/cmd_vel:=/cmd_vel</remapping> <!--<argument>/cmd_vel:=cmd_vel</argument>-->
        <remapping>/odom:=/odom</remapping>
      </ros>
      <update_rate>100.0</update_rate>
      <num_wheel_pairs>2</num_wheel_pairs>
      <odometry_frame>odom</odometry_frame>
      <left_joint>front_left_wheel_joint</left_joint>
      <left_joint>back_left_wheel_joint</left_joint>      
      <right_joint>front_right_wheel_joint</right_joint>
      <right_joint>back_right_wheel_joint</right_joint>
      <wheel_radius>${WHEEL_RAD}</wheel_radius>
      <wheel_diameter>${2*WHEEL_RAD}</wheel_diameter>
      <wheel_separation>${WHEEL_WID_SEP}</wheel_separation>
      <robot_base_frame>base_link</robot_base_frame>
     		
      <publish_odom>true</publish_odom>
      <publish_odom_tf>true</publish_odom_tf>
      <publish_wheel_tf>true</publish_wheel_tf>
    </plugin>
  </gazebo>
</robot>